try{
    myFun();
}
catch(err){
    console.log("oops an error has occured");
}